Workbook

Sheet Read me
B2: Verity: SASB mapping for materiality weights
B3: DRAFT FOR REVIEW: for the researcher to check and the supervisor to approve
B5: How the weights will work
B6: Rule | C6: A term counts more when its SASB category is material for the company's SASB industry. Otherwise it counts at the standard weight of 1.
B7: Example | C7: 'health and safety' counts 1.5 for a cement company (workforce safety is material in that industry) and 1.0 for a bank (it is not).
B8: Weight values | C8: 1.5 is the working value. Results will also be run at 1.25, 2.0 and unweighted, to show whether rankings depend on the exact number.
B10: What is in this workbook
B11: Company industries (Step 1) | C11: DRAFT: each of the 65 companies assigned one SASB industry, with the reason and a confidence level.
B12: Term mapping (Step 2) | C12: DRAFT: each of the 67 current terms assigned to a SASB category, plus its group (core, financial add-on or generic).
B13: Industry materiality | C13: DRAFT: for each of the 22 industries in the sample, SASB's disclosure topics and the category each belongs to. This is SASB's own content, so it needs checking against the SASB Standards Navigator, not deciding.
B14: SASB categories / SASB industries | C14: Reference lists that feed the drop-downs and the counts.
B15: Step 3: sign-off | C15: The researcher reviews the yellow columns on the three draft sheets, then the supervisor approves.
B17: How to review (yellow columns)
B18: Agree? | C18: Choose Yes or No from the drop-down.
B19: Change to | C19: If No, pick the correct SASB industry or category from the drop-down.
B20: Comment | C20: Any reason or question. Example: Agree? = No · Change to = Real Estate · Comment = 'most of its revenue is rental income'.
B21: Where to focus | C21: Rows marked Low or Medium confidence, and notes starting with QUESTION (shaded pink).
B23: Summary (updates automatically)
B24: Companies | C24: =COUNTA('Company industries'!B2:B66)
B25: SASB industries used | C25: =COUNTIF('SASB industries'!C2:C78,">0")
B26: Companies labelled financial in your list | C26: =COUNTIF('Company industries'!F2:F66,"Yes")
B27: Companies in SASB's Financials sector (would get the add-on) | C27: =COUNTIF('Company industries'!L2:L66,"Yes")
B28: Companies at Low confidence | C28: =COUNTIF('Company industries'!J2:J66,"Low")
B29: Terms in total | C29: =COUNTA('Term mapping'!C2:C68)
B30: Core terms (scored for every company) | C30: =COUNTIF('Term mapping'!D2:D68,"Core")
B31: Financial add-on terms | C31: =COUNTIF('Term mapping'!D2:D68,"Financial add-on")
B32: Core terms with no SASB category (always weight 1) | C32: =COUNTIFS('Term mapping'!D2:D68,"Core",'Term mapping'!E2:E68,"No SASB category")
B33: Average core terms with extra weight: banks | C33: =AVERAGEIF('Company industries'!H2:H66,"Commercial Banks",'Company industries'!M2:M66)
B34: Average core terms with extra weight: all other companies | C34: =AVERAGEIF('Company industries'!H2:H66,"<>Commercial Banks",'Company industries'!M2:M66)
B36: Points for the supervisor
B37: 1. Five companies are new to Verity | C37: Gulf Hotels Group, Jazeera Steel, Salam International Investment, Barwa Real Estate and Jazeera Airways. They have no market value in the list, so the sample is no longer purely 'top companies by market value'. The selection basis for these five needs a sentence in the methodology.
B38: 2. Two 'financial' labels change | C38: Saudi Industrial Investment Group (petrochemical holdings) and Dubai Investments (diversified, mainly property) are labelled Financial Services but are not financial businesses under SASB. Proposed: only companies in SASB's Financials sector get the financial add-on.
B39: 3. Judgement calls | C39: Property developers (Home Builders vs Real Estate have different material topics), integrated firms (Aramco, Petro Rabigh, Savola, Almarai, Industries Qatar), and four Low-confidence cases (CATRION, Dubai Investments, OMINVEST, Salam International).
B40: 4. Weighting mostly affects E and S | C40: SASB leaves board composition and similar governance topics outside its scope, so most Governance terms have no SASB category and stay at weight 1 for everyone.
B41: 5. Gap for non-banks | C41: Seven SASB categories have no Verity term (see 'SASB categories', column D = 0), including Air Quality and Critical Incident Risk Management. These are material for chemicals, cement, oil and gas, metals and airlines, which make up a large part of the sample.
B42: 6. Two term questions | C42: Should 'CSR' be counted with the generic terms? Should 'zakat' stay in the list?
B44: Sources
B45: Company list | C45: Updated_List_of_Companies.xlsx, supplied by the researcher (65 companies).
B46: SASB industries and categories | C46: SASB Standards: 77 industries (SICS) and 26 General Issue Categories in five dimensions. Verify in the SASB Standards Navigator: https://navigator.sasb.ifrs.org
B47: Industry materiality | C47: Drafted from the SASB industry standards' disclosure topics. Commercial Banks topics checked against published SASB indexes, which include the newer Financed Emissions topic. Other industries: verify each row.
...

Sheet Company industries
A1: # | B1: Company | C1: Symbol | D1: Country | E1: Industry (your list) | F1: Labelled financial today? | G1: SASB sector | H1: SASB industry | I1: Main business (basis for the choice) | J1: Confidence | K1: Note | L1: Gets financial add-on? (proposed) | M1: Core terms that get extra weight (draft) | N1: Agree? | O1: Change to | P1: Comment
A2: 1 | B2: Saudi Aramco | C2: 2222 | D2: Saudi Arabia | E2: Energy | F2: No | G2: =IFERROR(INDEX('SASB industries'!$A$2:$A$78,MATCH(H2,'SASB industries'!$B$2:$B$78,0)),"check name") | H2: Oil & Gas – Exploration & Production | I2: Integrated oil and gas; crude production is the core, with large refining and chemicals arms | J2: High | K2: Integrated firm. Alternative: Oil & Gas – Refining & Marketing. | L2: =IF(G2="Financials","Yes","No") | M2: =SUMPRODUCT(('Term mapping'!$D$2:$D$68="Core")*(((COUNTIFS('Industry materiality'!$A$2:$A$169,$H2,'Industry materiality'!$C$2:$C$169,'Term mapping'!$E$2:$E$68)+COUNTIFS('Industry materiality'!$A$2:$A$169,$H2,'Industry materiality'!$C$2:$C$169,'Term mapping'!$F$2:$F$68))>0)*1)) | N2: Yes
A3: 2 | B3: Al Rajhi Bank | C3: 1120 | D3: Saudi Arabia | E3: Financial Services | F3: Yes | G3: =IFERROR(INDEX('SASB industries'!$A$2:$A$78,MATCH(H3,'SASB industries'!$B$2:$B$78,0)),"check name") | H3: Commercial Banks | I3: Commercial bank | J3: High | L3: =IF(G3="Financials","Yes","No") | M3: =SUMPRODUCT(('Term mapping'!$D$2:$D$68="Core")*(((COUNTIFS('Industry materiality'!$A$2:$A$169,$H3,'Industry materiality'!$C$2:$C$169,'Term mapping'!$E$2:$E$68)+COUNTIFS('Industry materiality'!$A$2:$A$169,$H3,'Industry materiality'!$C$2:$C$169,'Term mapping'!$F$2:$F$68))>0)*1)) | N3: Yes
A4: 3 | B4: The Saudi National Bank | C4: 1180 | D4: Saudi Arabia | E4: Financial Services | F4: Yes | G4: =IFERROR(INDEX('SASB industries'!$A$2:$A$78,MATCH(H4,'SASB industries'!$B$2:$B$78,0)),"check name") | H4: Commercial Banks | I4: Commercial bank | J4: High | L4: =IF(G4="Financials","Yes","No") | M4: =SUMPRODUCT(('Term mapping'!$D$2:$D$68="Core")*(((COUNTIFS('Industry materiality'!$A$2:$A$169,$H4,'Industry materiality'!$C$2:$C$169,'Term mapping'!$E$2:$E$68)+COUNTIFS('Industry materiality'!$A$2:$A$169,$H4,'Industry materiality'!$C$2:$C$169,'Term mapping'!$F$2:$F$68))>0)*1)) | N4: Yes
A5: 4 | B5: Saudi Basic Industries Corporation SABIC | C5: 2010 | D5: Saudi Arabia | E5: Industrial | F5: No | G5: =IFERROR(INDEX('SASB industries'!$A$2:$A$78,MATCH(H5,'SASB industries'!$B$2:$B$78,0)),"check name") | H5: Chemicals | I5: Petrochemicals, polymers and specialty chemicals | J5: High | L5: =IF(G5="Financials","Yes","No") | M5: =SUMPRODUCT(('Term mapping'!$D$2:$D$68="Core")*(((COUNTIFS('Industry materiality'!$A$2:$A$169,$H5,'Industry materiality'!$C$2:$C$169,'Term mapping'!$E$2:$E$68)+COUNTIFS('Industry materiality'!$A$2:$A$169,$H5,'Industry materiality'!$C$2:$C$169,'Term mapping'!$F$2:$F$68))>0)*1)) | N5: Yes
A6: 5 | B6: Saudi Telecom Company | C6: 7010 | D6: Saudi Arabia | E6: Communication Services | F6: No | G6: =IFERROR(INDEX('SASB industries'!$A$2:$A$78,MATCH(H6,'SASB industries'!$B$2:$B$78,0)),"check name") | H6: Telecommunication Services | I6: Mobile, fixed and internet telecom operator | J6: High | L6: =IF(G6="Financials","Yes","No") | M6: =SUMPRODUCT(('Term mapping'!$D$2:$D$68="Core")*(((COUNTIFS('Industry materiality'!$A$2:$A$169,$H6,'Industry materiality'!$C$2:$C$169,'Term mapping'!$E$2:$E$68)+COUNTIFS('Industry materiality'!$A$2:$A$169,$H6,'Industry materiality'!$C$2:$C$169,'Term mapping'!$F$2:$F$68))>0)*1)) | N6: Yes
A7: 6 | B7: Maaden | C7: 1211 | D7: Saudi Arabia | E7: Industrial | F7: No | G7: =IFERROR(INDEX('SASB industries'!$A$2:$A$78,MATCH(H7,'SASB industries'!$B$2:$B$78,0)),"check name") | H7: Metals & Mining | I7: Phosphate, aluminium and gold mining and processing | J7: High | L7: =IF(G7="Financials","Yes","No") | M7: =SUMPRODUCT(('Term mapping'!$D$2:$D$68="Core")*(((COUNTIFS('Industry materiality'!$A$2:$A$169,$H7,'Industry materiality'!$C$2:$C$169,'Term mapping'!$E$2:$E$68)+COUNTIFS('Industry materiality'!$A$2:$A$169,$H7,'Industry materiality'!$C$2:$C$169,'Term mapping'!$F$2:$F$68))>0)*1)) | N7: Yes
A8: 7 | B8: Riyad Bank | C8: 1010 | D8: Saudi Arabia | E8: Financial Services | F8: Yes | G8: =IFERROR(INDEX('SASB industries'!$A$2:$A$78,MATCH(H8,'SASB industries'!$B$2:$B$78,0)),"check name") | H8: Commercial Banks | I8: Commercial bank | J8: High | L8: =IF(G8="Financials","Yes","No") | M8: =SUMPRODUCT(('Term mapping'!$D$2:$D$68="Core")*(((COUNTIFS('Industry materiality'!$A$2:$A$169,$H8,'Industry materiality'!$C$2:$C$169,'Term mapping'!$E$2:$E$68)+COUNTIFS('Industry materiality'!$A$2:$A$169,$H8,'Industry materiality'!$C$2:$C$169,'Term mapping'!$F$2:$F$68))>0)*1)) | N8: Yes
A9: 8 | B9: Alinma Bank | C9: 1150 | D9: Saudi Arabia | E9: Financial Services | F9: Yes | G9: =IFERROR(INDEX('SASB industries'!$A$2:$A$78,MATCH(H9,'SASB industries'!$B$2:$B$78,0)),"check name") | H9: Commercial Banks | I9: Commercial bank | J9: High | L9: =IF(G9="Financials","Yes","No") | M9: =SUMPRODUCT(('Term mapping'!$D$2:$D$68="Core")*(((COUNTIFS('Industry materiality'!$A$2:$A$169,$H9,'Industry materiality'!$C$2:$C$169,'Term mapping'!$E$2:$E$68)+COUNTIFS('Industry materiality'!$A$2:$A$169,$H9,'Industry materiality'!$C$2:$C$169,'Term mapping'!$F$2:$F$68))>0)*1)) | N9: Yes
A10: 9 | B10: Yanbu Cement Company | C10: 3060 | D10: Saudi Arabia | E10: Industrial | F10: No | G10: =IFERROR(INDEX('SASB industries'!$A$2:$A$78,MATCH(H10,'SASB industries'!$B$2:$B$78,0)),"check name") | H10: Construction Materials | I10: Cement production | J10: High | L10: =IF(G10="Financials","Yes","No") | M10: =SUMPRODUCT(('Term mapping'!$D$2:$D$68="Core")*(((COUNTIFS('Industry materiality'!$A$2:$A$169,$H10,'Industry materiality'!$C$2:$C$169,'Term mapping'!$E$2:$E$68)+COUNTIFS('Industry materiality'!$A$2:$A$169,$H10,'Industry materiality'!$C$2:$C$169,'Term mapping'!$F$2:$F$68))>0)*1)) | N10: Yes
A11: 10 | B11: SABIC Agri-Nutrients Company | C11: 2020 | D11: Saudi Arabia | E11: Industrial | F11: No | G11: =IFERROR(INDEX('SASB industries'!$A$2:$A$78,MATCH(H11,'SASB industries'!$B$2:$B$78,0)),"check name") | H11: Chemicals | I11: Fertilisers (ammonia, urea) | J11: High | K11: SASB places fertiliser producers under Chemicals. | L11: =IF(G11="Financials","Yes","No") | M11: =SUMPRODUCT(('Term mapping'!$D$2:$D$68="Core")*(((COUNTIFS('Industry materiality'!$A$2:$A$169,$H11,'Industry materiality'!$C$2:$C$169,'Term mapping'!$E$2:$E$68)+COUNTIFS('Industry materiality'!$A$2:$A$169,$H11,'Industry materiality'!$C$2:$C$169,'Term mapping'!$F$2:$F$68))>0)*1)) | N11: Yes
A12: 11 | B12: Almarai | C12: 2280 | D12: Saudi Arabia | E12: Consumer Defensive | F12: No | G12: =IFERROR(INDEX('SASB industries'!$A$2:$A$78,MATCH(H12,'SASB industries'!$B$2:$B$78,0)),"check name") | H12: Meat, Poultry & Dairy | I12: Dairy, juice, bakery and poultry | J12: Medium | K12: Alternative: Processed Foods. | L12: =IF(G12="Financials","Yes","No") | M12: =SUMPRODUCT(('Term mapping'!$D$2:$D$68="Core")*(((COUNTIFS('Industry materiality'!$A$2:$A$169,$H12,'Industry materiality'!$C$2:$C$169,'Term mapping'!$E$2:$E$68)+COUNTIFS('Industry materiality'!$A$2:$A$169,$H12,'Industry materiality'!$C$2:$C$169,'Term mapping'!$F$2:$F$68))>0)*1)) | N12: Yes
A13: 12 | B13: Bank Albilad | C13: 1140 | D13: Saudi Arabia | E13: Financial Services | F13: Yes | G13: =IFERROR(INDEX('SASB industries'!$A$2:$A$78,MATCH(H13,'SASB industries'!$B$2:$B$78,0)),"check name") | H13: Commercial Banks | I13: Commercial bank | J13: High | L13: =IF(G13="Financials","Yes","No") | M13: =SUMPRODUCT(('Term mapping'!$D$2:$D$68="Core")*(((COUNTIFS('Industry materiality'!$A$2:$A$169,$H13,'Industry materiality'!$C$2:$C$169,'Term mapping'!$E$2:$E$68)+COUNTIFS('Industry materiality'!$A$2:$A$169,$H13,'Industry materiality'!$C$2:$C$169,'Term mapping'!$F$2:$F$68))>0)*1)) | N13: Yes
A14: 13 | B14: Etihad Etisalat (Mobily) | C14: 7020 | D14: Saudi Arabia | E14: Communication Services | F14: No | G14: =IFERROR(INDEX('SASB industries'!$A$2:$A$78,MATCH(H14,'SASB industries'!$B$2:$B$78,0)),"check name") | H14: Telecommunication Services | I14: Mobile, fixed and internet telecom operator | J14: High | L14: =IF(G14="Financials","Yes","No") | M14: =SUMPRODUCT(('Term mapping'!$D$2:$D$68="Core")*(((COUNTIFS('Industry materiality'!$A$2:$A$169,$H14,'Industry materiality'!$C$2:$C$169,'Term mapping'!$E$2:$E$68)+COUNTIFS('Industry materiality'!$A$2:$A$169,$H14,'Industry materiality'!$C$2:$C$169,'Term mapping'!$F$2:$F$68))>0)*1)) | N14: Yes
A15: 14 | B15: Savola Group | C15: 2050 | D15: Saudi Arabia | E15: Consumer Defensive | F15: No | G15: =IFERROR(INDEX('SASB industries'!$A$2:$A$78,MATCH(H15,'SASB industries'!$B$2:$B$78,0)),"check name") | H15: Processed Foods | I15: Edible oils, sugar and pasta, plus a large supermarket chain (Panda) | J15: Medium | K15: Alternative: Food Retailers & Distributors, depending on which segment is larger. | L15: =IF(G15="Financials","Yes","No") | M15: =SUMPRODUCT(('Term mapping'!$D$2:$D$68="Core")*(((COUNTIFS('Industry materiality'!$A$2:$A$169,$H15,'Industry materiality'!$C$2:$C$169,'Term mapping'!$E$2:$E$68)+COUNTIFS('Industry materiality'!$A$2:$A$169,$H15,'Industry materiality'!$C$2:$C$169,'Term mapping'!$F$2:$F$68))>0)*1)) | N15: Yes
A16: 15 | B16: Yanbu National Petrochemical Co | C16: 2290 | D16: Saudi Arabia | E16: Industrial | F16: No | G16: =IFERROR(INDEX('SASB industries'!$A$2:$A$78,MATCH(H16,'SASB industries'!$B$2:$B$78,0)),"check name") | H16: Chemicals | I16: Petrochemicals | J16: High | L16: =IF(G16="Financials","Yes","No") | M16: =SUMPRODUCT(('Term mapping'!$D$2:$D$68="Core")*(((COUNTIFS('Industry materiality'!$A$2:$A$169,$H16,'Industry materiality'!$C$2:$C$169,'Term mapping'!$E$2:$E$68)+COUNTIFS('Industry materiality'!$A$2:$A$169,$H16,'Industry materiality'!$C$2:$C$169,'Term mapping'!$F$2:$F$68))>0)*1)) | N16: Yes
A17: 16 | B17: Dar Al Arkan Real Estate Development Company | C17: 4300 | D17: Saudi Arabia | E17: Real Estate | F17: No | G17: =IFERROR(INDEX('SASB industries'!$A$2:$A$78,MATCH(H17,'SASB industries'!$B$2:$B$78,0)),"check name") | H17: Home Builders | I17: Land and residential development for sale | J17: Medium | K17: Alternative: Real Estate. The two have different material topics, so this choice matters. | L17: =IF(G17="Financials","Yes","No") | M17: =SUMPRODUCT(('Term mapping'!$D$2:$D$68="Core")*(((COUNTIFS('Industry materiality'!$A$2:$A$169,$H17,'Industry materiality'!$C$2:$C$169,'Term mapping'!$E$2:$E$68)+COUNTIFS('Industry materiality'!$A$2:$A$169,$H17,'Industry materiality'!$C$2:$C$169,'Term mapping'!$F$2:$F$68))>0)*1)) | N17: Yes
A18: 17 | B18: Advanced Petrochemical | C18: 2330 | D18: Saudi Arabia | E18: Industrial | F18: No | G18: =IFERROR(INDEX('SASB industries'!$A$2:$A$78,MATCH(H18,'SASB industries'!$B$2:$B$78,0)),"check name") | H18: Chemicals | I18: Polypropylene and other petrochemicals | J18: High | L18: =IF(G18="Financials","Yes","No") | M18: =SUMPRODUCT(('Term mapping'!$D$2:$D$68="Core")*(((COUNTIFS('Industry materiality'!$A$2:$A$169,$H18,'Industry materiality'!$C$2:$C$169,'Term mapping'!$E$2:$E$68)+COUNTIFS('Industry materiality'!$A$2:$A$169,$H18,'Industry materiality'!$C$2:$C$169,'Term mapping'!$F$2:$F$68))>0)*1)) | N18: Yes
A19: 18 | B19: Mouwasat Medical Services Company | C19: 4002 | D19: Saudi Arabia | E19: Healthcare | F19: No | G19: =IFERROR(INDEX('SASB industries'!$A$2:$A$78,MATCH(H19,'SASB industries'!$B$2:$B$78,0)),"check name") | H19: Health Care Delivery | I19: Private hospitals and clinics | J19: High | L19: =IF(G19="Financials","Yes","No") | M19: =SUMPRODUCT(('Term mapping'!$D$2:$D$68="Core")*(((COUNTIFS('Industry materiality'!$A$2:$A$169,$H19,'Industry materiality'!$C$2:$C$169,'Term mapping'!$E$2:$E$68)+COUNTIFS('Industry materiality'!$A$2:$A$169,$H19,'Industry materiality'!$C$2:$C$169,'Term mapping'!$F$2:$F$68))>0)*1)) | N19: Yes
A20: 19 | B20: Saudi Airlines Catering Company CATRION | C20: 6004 | D20: Saudi Arabia | E20: Consumer Cyclical | F20: No | G20: =IFERROR(INDEX('SASB industries'!$A$2:$A$78,MATCH(H20,'SASB industries'!$B$2:$B$78,0)),"check name") | H20: Restaurants | I20: Airline and institutional catering | J20: Low | K20: No exact SASB match for catering. Restaurants is the closest (food safety, nutrition, food waste). | L20: =IF(G20="Financials","Yes","No") | M20: =SUMPRODUCT(('Term mapping'!$D$2:$D$68="Core")*(((COUNTIFS('Industry materiality'!$A$2:$A$169,$H20,'Industry materiality'!$C$2:$C$169,'Term mapping'!$E$2:$E$68)+COUNTIFS('Industry materiality'!$A$2:$A$169,$H20,'Industry materiality'!$C$2:$C$169,'Term mapping'!$F$2:$F$68))>0)*1)) | N20: Yes
A21: 20 | B21: National Industrialization Co | C21: 2060 | D21: Saudi Arabia | E21: Industrial | F21: No | G21: =IFERROR(INDEX('SASB industries'!$A$2:$A$78,MATCH(H21,'SASB industries'!$B$2:$B$78,0)),"check name") | H21: Chemicals | I21: Petrochemicals and titanium dioxide | J21: High | L21: =IF(G21="Financials","Yes","No") | M21: =SUMPRODUCT(('Term mapping'!$D$2:$D$68="Core")*(((COUNTIFS('Industry materiality'!$A$2:$A$169,$H21,'Industry materiality'!$C$2:$C$169,'Term mapping'!$E$2:$E$68)+COUNTIFS('Industry materiality'!$A$2:$A$169,$H21,'Industry materiality'!$C$2:$C$169,'Term mapping'!$F$2:$F$68))>0)*1)) | N21: Yes
A22: 21 | B22: Rabigh Refining & Petrochemical Co. | C22: 2380 | D22: Saudi Arabia | E22: Industrial | F22: No | G22: =IFERROR(INDEX('SASB industries'!$A$2:$A$78,MATCH(H22,'SASB industries'!$B$2:$B$78,0)),"check name") | H22: Oil & Gas – Refining & Marketing | I22: Integrated refinery and petrochemical complex | J22: Medium | K22: Alternative: Chemicals. | L22: =IF(G22="Financials","Yes","No") | M22: =SUMPRODUCT(('Term mapping'!$D$2:$D$68="Core")*(((COUNTIFS('Industry materiality'!$A$2:$A$169,$H22,'Industry materiality'!$C$2:$C$169,'Term mapping'!$E$2:$E$68)+COUNTIFS('Industry materiality'!$A$2:$A$169,$H22,'Industry materiality'!$C$2:$C$169,'Term mapping'!$F$2:$F$68))>0)*1)) | N22: Yes
A23: 22 | B23: Sahara International Petrochemical Co. | C23: 2310 | D23: Saudi Arabia | E23: Industrial | F23: No | G23: =IFERROR(INDEX('SASB industries'!$A$2:$A$78,MATCH(H23,'SASB industries'!$B$2:$B$78,0)),"check name") | H23: Chemicals | I23: Petrochemicals | J23: High | L23: =IF(G23="Financials","Yes","No") | M23: =SUMPRODUCT(('Term mapping'!$D$2:$D$68="Core")*(((COUNTIFS('Industry materiality'!$A$2:$A$169,$H23,'Industry materiality'!$C$2:$C$169,'Term mapping'!$E$2:$E$68)+COUNTIFS('Industry materiality'!$A$2:$A$169,$H23,'Industry materiality'!$C$2:$C$169,'Term mapping'!$F$2:$F$68))>0)*1)) | N23: Yes
A24: 23 | B24: Mobile Telecommunications Co. Saudi Arabia (Zain) | C24: 7030 | D24: Saudi Arabia | E24: Communication Services | F24: No | G24: =IFERROR(INDEX('SASB industries'!$A$2:$A$78,MATCH(H24,'SASB industries'!$B$2:$B$78,0)),"check name") | H24: Telecommunication Services | I24: Mobile, fixed and internet telecom operator | J24: High | L24: =IF(G24="Financials","Yes","No") | M24: =SUMPRODUCT(('Term mapping'!$D$2:$D$68="Core")*(((COUNTIFS('Industry materiality'!$A$2:$A$169,$H24,'Industry materiality'!$C$2:$C$169,'Term mapping'!$E$2:$E$68)+COUNTIFS('Industry materiality'!$A$2:$A$169,$H24,'Industry materiality'!$C$2:$C$169,'Term mapping'!$F$2:$F$68))>0)*1)) | N24: Yes
A25: 24 | B25: Jarir Marketing Co | C25: 4190 | D25: Saudi Arabia | E25: Consumer Discretionary | F25: No | G25: =IFERROR(INDEX('SASB industries'!$A$2:$A$78,MATCH(H25,'SASB industries'!$B$2:$B$78,0)),"check name") | H25: Multiline and Specialty Retailers & Distributors | I25: Retail of books, office supplies and electronics | J25: High | L25: =IF(G25="Financials","Yes","No") | M25: =SUMPRODUCT(('Term mapping'!$D$2:$D$68="Core")*(((COUNTIFS('Industry materiality'!$A$2:$A$169,$H25,'Industry materiality'!$C$2:$C$169,'Term mapping'!$E$2:$E$68)+COUNTIFS('Industry materiality'!$A$2:$A$169,$H25,'Industry materiality'!$C$2:$C$169,'Term mapping'!$F$2:$F$68))>0)*1)) | N25: Yes
A26: 25 | B26: Saudi Cement | C26: 3030 | D26: Saudi Arabia | E26: Industrial | F26: No | G26: =IFERROR(INDEX('SASB industries'!$A$2:$A$78,MATCH(H26,'SASB industries'!$B$2:$B$78,0)),"check name") | H26: Construction Materials | I26: Cement production | J26: High | L26: =IF(G26="Financials","Yes","No") | M26: =SUMPRODUCT(('Term mapping'!$D$2:$D$68="Core")*(((COUNTIFS('Industry materiality'!$A$2:$A$169,$H26,'Industry materiality'!$C$2:$C$169,'Term mapping'!$E$2:$E$68)+COUNTIFS('Industry materiality'!$A$2:$A$169,$H26,'Industry materiality'!$C$2:$C$169,'Term mapping'!$F$2:$F$68))>0)*1)) | N26: Yes
A27: 26 | B27: Abdullah Al Othaim Markets | C27: 4001 | D27: Saudi Arabia | E27: Consumer Defensive | F27: No | G27: =IFERROR(INDEX('SASB industries'!$A$2:$A$78,MATCH(H27,'SASB industries'!$B$2:$B$78,0)),"check name") | H27: Food Retailers & Distributors | I27: Supermarket chain | J27: High | L27: =IF(G27="Financials","Yes","No") | M27: =SUMPRODUCT(('Term mapping'!$D$2:$D$68="Core")*(((COUNTIFS('Industry materiality'!$A$2:$A$169,$H27,'Industry materiality'!$C$2:$C$169,'Term mapping'!$E$2:$E$68)+COUNTIFS('Industry materiality'!$A$2:$A$169,$H27,'Industry materiality'!$C$2:$C$169,'Term mapping'!$F$2:$F$68))>0)*1)) | N27: Yes
A28: 27 | B28: Saudi Industrial Investment Group | C28: 2250 | D28: Saudi Arabia | E28: Financial Services | F28: Yes | G28: =IFERROR(INDEX('SASB industries'!$A$2:$A$78,MATCH(H28,'SASB industries'!$B$2:$B$78,0)),"check name") | H28: Chemicals | I28: Holding company whose investments are petrochemical joint ventures | J28: Medium | K28: QUESTION: labelled Financial Services in the list, but the underlying business is petrochemicals.; Replaced by Bank Aljazira (1020) 2026-10-21 | L28: =IF(G28="Financials","Yes","No") | M28: =SUMPRODUCT(('Term mapping'!$D$2:$D$68="Core")*(((COUNTIFS('Industry materiality'!$A$2:$A$169,$H28,'Industry materiality'!$C$2:$C$169,'Term mapping'!$E$2:$E$68)+COUNTIFS('Industry materiality'!$A$2:$A$169,$H28,'Industry materiality'!$C$2:$C$169,'Term mapping'!$F$2:$F$68))>0)*1)) | N28: Yes
A29: 28 | B29: Abu Dhabi National Oil Company For Distribution | C29: ADNOCDIST | D29: United Arab Emirates | E29: Energy | F29: No | G29: =IFERROR(INDEX('SASB industries'!$A$2:$A$78,MATCH(H29,'SASB industries'!$B$2:$B$78,0)),"check name") | H29: Oil & Gas – Refining & Marketing | I29: Fuel retail stations and fuel distribution | J29: High | K29: SASB includes fuel retail under Refining & Marketing. | L29: =IF(G29="Financials","Yes","No") | M29: =SUMPRODUCT(('Term mapping'!$D$2:$D$68="Core")*(((COUNTIFS('Industry materiality'!$A$2:$A$169,$H29,'Industry materiality'!$C$2:$C$169,'Term mapping'!$E$2:$E$68)+COUNTIFS('Industry materiality'!$A$2:$A$169,$H29,'Industry materiality'!$C$2:$C$169,'Term mapping'!$F$2:$F$68))>0)*1)) | N29: Yes
A30: 29 | B30: Emirates Telecom (Etisalat Group) | C30: EAND | D30: United Arab Emirates | E30: Communication Services | F30: No | G30: =IFERROR(INDEX('SASB industries'!$A$2:$A$78,MATCH(H30,'SASB industries'!$B$2:$B$78,0)),"check name") | H30: Telecommunication Services | I30: Mobile, fixed and internet telecom operator | J30: High | L30: =IF(G30="Financials","Yes","No") | M30: =SUMPRODUCT(('Term mapping'!$D$2:$D$68="Core")*(((COUNTIFS('Industry materiality'!$A$2:$A$169,$H30,'Industry materiality'!$C$2:$C$169,'Term mapping'!$E$2:$E$68)+COUNTIFS('Industry materiality'!$A$2:$A$169,$H30,'Industry materiality'!$C$2:$C$169,'Term mapping'!$F$2:$F$68))>0)*1)) | N30: Yes
A31: 30 | B31: First Abu Dhabi Bank | C31: FAB | D31: United Arab Emirates | E31: Financial Services | F31: Yes | G31: =IFERROR(INDEX('SASB industries'!$A$2:$A$78,MATCH(H31,'SASB industries'!$B$2:$B$78,0)),"check name") | H31: Commercial Banks | I31: Commercial bank | J31: High | L31: =IF(G31="Financials","Yes","No") | M31: =SUMPRODUCT(('Term mapping'!$D$2:$D$68="Core")*(((COUNTIFS('Industry materiality'!$A$2:$A$169,$H31,'Industry materiality'!$C$2:$C$169,'Term mapping'!$E$2:$E$68)+COUNTIFS('Industry materiality'!$A$2:$A$169,$H31,'Industry materiality'!$C$2:$C$169,'Term mapping'!$F$2:$F$68))>0)*1)) | N31: Yes
A32: 31 | B32: Abu Dhabi National Energy Company | C32: TAQA | D32: United Arab Emirates | E32: Energy | F32: No | G32: =IFERROR(INDEX('SASB industries'!$A$2:$A$78,MATCH(H32,'SASB industries'!$B$2:$B$78,0)),"check name") | H32: Electric Utilities & Power Generators | I32: Power and water generation, transmission and distribution; some oil and gas | J32: High | L32: =IF(G32="Financials","Yes","No") | M32: =SUMPRODUCT(('Term mapping'!$D$2:$D$68="Core")*(((COUNTIFS('Industry materiality'!$A$2:$A$169,$H32,'Industry materiality'!$C$2:$C$169,'Term mapping'!$E$2:$E$68)+COUNTIFS('Industry materiality'!$A$2:$A$169,$H32,'Industry materiality'!$C$2:$C$169,'Term mapping'!$F$2:$F$68))>0)*1)) | N32: Yes
A33: 32 | B33: Abu Dhabi Commercial Bank | C33: ADCB | D33: United Arab Emirates | E33: Financial Services | F33: Yes | G33: =IFERROR(INDEX('SASB industries'!$A$2:$A$78,MATCH(H33,'SASB industries'!$B$2:$B$78,0)),"check name") | H33: Commercial Banks | I33: Commercial bank | J33: High | L33: =IF(G33="Financials","Yes","No") | M33: =SUMPRODUCT(('Term mapping'!$D$2:$D$68="Core")*(((COUNTIFS('Industry materiality'!$A$2:$A$169,$H33,'Industry materiality'!$C$2:$C$169,'Term mapping'!$E$2:$E$68)+COUNTIFS('Industry materiality'!$A$2:$A$169,$H33,'Industry materiality'!$C$2:$C$169,'Term mapping'!$F$2:$F$68))>0)*1)) | N33: Yes
A34: 33 | B34: Aldar Properties PJSC | C34: ALDAR | D34: United Arab Emirates | E34: Real Estate | F34: No | G34: =IFERROR(INDEX('SASB industries'!$A$2:$A$78,MATCH(H34,'SASB industries'!$B$2:$B$78,0)),"check name") | H34: Real Estate | I34: Property development plus a large rental (investment) portfolio | J34: Medium | K34: Alternative: Home Builders. | L34: =IF(G34="Financials","Yes","No") | M34: =SUMPRODUCT(('Term mapping'!$D$2:$D$68="Core")*(((COUNTIFS('Industry materiality'!$A$2:$A$169,$H34,'Industry materiality'!$C$2:$C$169,'Term mapping'!$E$2:$E$68)+COUNTIFS('Industry materiality'!$A$2:$A$169,$H34,'Industry materiality'!$C$2:$C$169,'Term mapping'!$F$2:$F$68))>0)*1)) | N34: Yes
A35: 34 | B35: The National Bank of Ras Al Khaimah | C35: RAKBANK | D35: United Arab Emirates | E35: Financial Services | F35: Yes | G35: =IFERROR(INDEX('SASB industries'!$A$2:$A$78,MATCH(H35,'SASB industries'!$B$2:$B$78,0)),"check name") | H35: Commercial Banks | I35: Commercial bank | J35: High | L35: =IF(G35="Financials","Yes","No") | M35: =SUMPRODUCT(('Term mapping'!$D$2:$D$68="Core")*(((COUNTIFS('Industry materiality'!$A$2:$A$169,$H35,'Industry materiality'!$C$2:$C$169,'Term mapping'!$E$2:$E$68)+COUNTIFS('Industry materiality'!$A$2:$A$169,$H35,'Industry materiality'!$C$2:$C$169,'Term mapping'!$F$2:$F$68))>0)*1)) | N35: Yes
A36: 35 | B36: Emaar Properties | C36: EMAAR | D36: United Arab Emirates | E36: Real Estate | F36: No | G36: =IFERROR(INDEX('SASB industries'!$A$2:$A$78,MATCH(H36,'SASB industries'!$B$2:$B$78,0)),"check name") | H36: Home Builders | I36: Master-planned residential development for sale, plus malls and hotels | J36: Medium | K36: Alternative: Real Estate. | L36: =IF(G36="Financials","Yes","No") | M36: =SUMPRODUCT(('Term mapping'!$D$2:$D$68="Core")*(((COUNTIFS('Industry materiality'!$A$2:$A$169,$H36,'Industry materiality'!$C$2:$C$169,'Term mapping'!$E$2:$E$68)+COUNTIFS('Industry materiality'!$A$2:$A$169,$H36,'Industry materiality'!$C$2:$C$169,'Term mapping'!$F$2:$F$68))>0)*1)) | N36: Yes
A37: 36 | B37: Dubai Islamic Bank | C37: DIB | D37: United Arab Emirates | E37: Financial Services | F37: Yes | G37: =IFERROR(INDEX('SASB industries'!$A$2:$A$78,MATCH(H37,'SASB industries'!$B$2:$B$78,0)),"check name") | H37: Commercial Banks | I37: Commercial bank | J37: High | L37: =IF(G37="Financials","Yes","No") | M37: =SUMPRODUCT(('Term mapping'!$D$2:$D$68="Core")*(((COUNTIFS('Industry materiality'!$A$2:$A$169,$H37,'Industry materiality'!$C$2:$C$169,'Term mapping'!$E$2:$E$68)+COUNTIFS('Industry materiality'!$A$2:$A$169,$H37,'Industry materiality'!$C$2:$C$169,'Term mapping'!$F$2:$F$68))>0)*1)) | N37: Yes
A38: 37 | B38: Dubai Investments PJSC | C38: DIC | D38: United Arab Emirates | E38: Financial Services | F38: Yes | G38: =IFERROR(INDEX('SASB industries'!$A$2:$A$78,MATCH(H38,'SASB industries'!$B$2:$B$78,0)),"check name") | H38: Real Estate | I38: Diversified group: property, manufacturing and investments | J38: Low | K38: QUESTION: labelled Financial Services in the list. Property is assumed to be the largest segment; check the segment split in its annual report. | L38: =IF(G38="Financials","Yes","No") | M38: =SUMPRODUCT(('Term mapping'!$D$2:$D$68="Core")*(((COUNTIFS('Industry materiality'!$A$2:$A$169,$H38,'Industry materiality'!$C$2:$C$169,'Term mapping'!$E$2:$E$68)+COUNTIFS('Industry materiality'!$A$2:$A$169,$H38,'Industry materiality'!$C$2:$C$169,'Term mapping'!$F$2:$F$68))>0)*1)) | N38: Yes
A39: 38 | B39: Air Arabia PJSC | C39: AIRA | D39: United Arab Emirates | E39: Consumer Discretionary | F39: No | G39: =IFERROR(INDEX('SASB industries'!$A$2:$A$78,MATCH(H39,'SASB industries'!$B$2:$B$78,0)),"check name") | H39: Airlines | I39: Low-cost airline | J39: High | L39: =IF(G39="Financials","Yes","No") | M39: =SUMPRODUCT(('Term mapping'!$D$2:$D$68="Core")*(((COUNTIFS('Industry materiality'!$A$2:$A$169,$H39,'Industry materiality'!$C$2:$C$169,'Term mapping'!$E$2:$E$68)+COUNTIFS('Industry materiality'!$A$2:$A$169,$H39,'Industry materiality'!$C$2:$C$169,'Term mapping'!$F$2:$F$68))>0)*1)) | N39: Yes
A40: 39 | B40: Emirates NBD PJSC | C40: NBD | D40: United Arab Emirates | E40: Financial Services | F40: Yes | G40: =IFERROR(INDEX('SASB industries'!$A$2:$A$78,MATCH(H40,'SASB industries'!$B$2:$B$78,0)),"check name") | H40: Commercial Banks | I40: Commercial bank | J40: High | L40: =IF(G40="Financials","Yes","No") | M40: =SUMPRODUCT(('Term mapping'!$D$2:$D$68="Core")*(((COUNTIFS('Industry materiality'!$A$2:$A$169,$H40,'Industry materiality'!$C$2:$C$169,'Term mapping'!$E$2:$E$68)+COUNTIFS('Industry materiality'!$A$2:$A$169,$H40,'Industry materiality'!$C$2:$C$169,'Term mapping'!$F$2:$F$68))>0)*1)) | N40: Yes
...

Sheet Term mapping
A1: # | B1: Pillar (today) | C1: Term | D1: Group | E1: SASB category (primary) | F1: SASB category (secondary) | G1: SASB dimension | H1: Confidence | I1: Note | J1: Agree? | K1: Change to | L1: Comment
A2: 1 | B2: Environmental | C2: climate change | D2: Core | E2: GHG Emissions | F2: Physical Impacts of Climate Change | G2: =IF(OR(E2="",E2="No SASB category"),"",IFERROR(INDEX('SASB categories'!$A$2:$A$27,MATCH(E2,'SASB categories'!$B$2:$B$27,0)),"check name")) | H2: Medium | I2: Covers both cutting emissions and coping with climate effects. | J2: Yes
A3: 2 | B3: Environmental | C3: climate risk | D3: Core | E3: Physical Impacts of Climate Change | F3: Business Model Resilience | G3: =IF(OR(E3="",E3="No SASB category"),"",IFERROR(INDEX('SASB categories'!$A$2:$A$27,MATCH(E3,'SASB categories'!$B$2:$B$27,0)),"check name")) | H3: Medium | I3: Physical risk sits under Physical Impacts; transition risk under Business Model Resilience. | J3: Yes
A4: 3 | B4: Environmental | C4: carbon emissions | D4: Core | E4: GHG Emissions | G4: =IF(OR(E4="",E4="No SASB category"),"",IFERROR(INDEX('SASB categories'!$A$2:$A$27,MATCH(E4,'SASB categories'!$B$2:$B$27,0)),"check name")) | H4: High | J4: Yes
A5: 4 | B5: Environmental | C5: carbon footprint | D5: Core | E5: GHG Emissions | G5: =IF(OR(E5="",E5="No SASB category"),"",IFERROR(INDEX('SASB categories'!$A$2:$A$27,MATCH(E5,'SASB categories'!$B$2:$B$27,0)),"check name")) | H5: High | J5: Yes
A6: 5 | B6: Environmental | C6: greenhouse gas | D6: Core | E6: GHG Emissions | G6: =IF(OR(E6="",E6="No SASB category"),"",IFERROR(INDEX('SASB categories'!$A$2:$A$27,MATCH(E6,'SASB categories'!$B$2:$B$27,0)),"check name")) | H6: High | J6: Yes
A7: 6 | B7: Environmental | C7: renewable energy | D7: Core | E7: Energy Management | G7: =IF(OR(E7="",E7="No SASB category"),"",IFERROR(INDEX('SASB categories'!$A$2:$A$27,MATCH(E7,'SASB categories'!$B$2:$B$27,0)),"check name")) | H7: High | J7: Yes
A8: 7 | B8: Environmental | C8: energy efficiency | D8: Core | E8: Energy Management | G8: =IF(OR(E8="",E8="No SASB category"),"",IFERROR(INDEX('SASB categories'!$A$2:$A$27,MATCH(E8,'SASB categories'!$B$2:$B$27,0)),"check name")) | H8: High | J8: Yes
A9: 8 | B9: Environmental | C9: green financing | D9: Financial add-on | E9: Product Design & Lifecycle Management | G9: =IF(OR(E9="",E9="No SASB category"),"",IFERROR(INDEX('SASB categories'!$A$2:$A$27,MATCH(E9,'SASB categories'!$B$2:$B$27,0)),"check name")) | H9: Medium | I9: For banks, SASB treats ESG in lending as a product-design topic. Verify in the SASB Navigator. | J9: Yes
A10: 9 | B10: Environmental | C10: green bond | D10: Core | E10: No SASB category | G10: =IF(OR(E10="",E10="No SASB category"),"",IFERROR(INDEX('SASB categories'!$A$2:$A$27,MATCH(E10,'SASB categories'!$B$2:$B$27,0)),"check name")) | H10: Medium | I10: Any company can issue one, so kept in the core. GCC firms often issue 'green sukuk', which this term does not catch: possible gap. | J10: Yes
A11: 10 | B11: Environmental | C11: sustainable finance | D11: Financial add-on | E11: Product Design & Lifecycle Management | G11: =IF(OR(E11="",E11="No SASB category"),"",IFERROR(INDEX('SASB categories'!$A$2:$A$27,MATCH(E11,'SASB categories'!$B$2:$B$27,0)),"check name")) | H11: Medium | I11: Same reasoning as green financing. Verify. | J11: Yes
A12: 11 | B12: Environmental | C12: environmental risk | D12: Core | E12: No SASB category | G12: =IF(OR(E12="",E12="No SASB category"),"",IFERROR(INDEX('SASB categories'!$A$2:$A$27,MATCH(E12,'SASB categories'!$B$2:$B$27,0)),"check name")) | H12: Medium | I12: Too broad to tie to one category. | J12: Yes
A13: 12 | B13: Environmental | C13: water management | D13: Core | E13: Water & Wastewater Management | G13: =IF(OR(E13="",E13="No SASB category"),"",IFERROR(INDEX('SASB categories'!$A$2:$A$27,MATCH(E13,'SASB categories'!$B$2:$B$27,0)),"check name")) | H13: High | J13: Yes
A14: 13 | B14: Environmental | C14: waste management | D14: Core | E14: Waste & Hazardous Materials Management | G14: =IF(OR(E14="",E14="No SASB category"),"",IFERROR(INDEX('SASB categories'!$A$2:$A$27,MATCH(E14,'SASB categories'!$B$2:$B$27,0)),"check name")) | H14: High | J14: Yes
A15: 14 | B15: Environmental | C15: biodiversity | D15: Core | E15: Ecological Impacts | G15: =IF(OR(E15="",E15="No SASB category"),"",IFERROR(INDEX('SASB categories'!$A$2:$A$27,MATCH(E15,'SASB categories'!$B$2:$B$27,0)),"check name")) | H15: High | J15: Yes
A16: 15 | B16: Environmental | C16: ESG | D16: Generic – counted separately | G16: =IF(OR(E16="",E16="No SASB category"),"",IFERROR(INDEX('SASB categories'!$A$2:$A$27,MATCH(E16,'SASB categories'!$B$2:$B$27,0)),"check name")) | I16: Agreed decision 3: counted separately, not as Environmental. | J16: Yes
A17: 16 | B17: Environmental | C17: sustainability | D17: Generic – counted separately | G17: =IF(OR(E17="",E17="No SASB category"),"",IFERROR(INDEX('SASB categories'!$A$2:$A$27,MATCH(E17,'SASB categories'!$B$2:$B$27,0)),"check name")) | I17: Agreed decision 3. | J17: Yes
A18: 17 | B18: Environmental | C18: GRI | D18: Generic – counted separately | G18: =IF(OR(E18="",E18="No SASB category"),"",IFERROR(INDEX('SASB categories'!$A$2:$A$27,MATCH(E18,'SASB categories'!$B$2:$B$27,0)),"check name")) | I18: Agreed decision 3. | J18: Yes
A19: 18 | B19: Environmental | C19: net zero | D19: Core | E19: GHG Emissions | G19: =IF(OR(E19="",E19="No SASB category"),"",IFERROR(INDEX('SASB categories'!$A$2:$A$27,MATCH(E19,'SASB categories'!$B$2:$B$27,0)),"check name")) | H19: High | J19: Yes
A20: 19 | B20: Environmental | C20: sustainable development | D20: Generic – counted separately | G20: =IF(OR(E20="",E20="No SASB category"),"",IFERROR(INDEX('SASB categories'!$A$2:$A$27,MATCH(E20,'SASB categories'!$B$2:$B$27,0)),"check name")) | I20: Agreed decision 3. | J20: Yes
A21: 20 | B21: Environmental | C21: sustainable financing | D21: Financial add-on | E21: Product Design & Lifecycle Management | G21: =IF(OR(E21="",E21="No SASB category"),"",IFERROR(INDEX('SASB categories'!$A$2:$A$27,MATCH(E21,'SASB categories'!$B$2:$B$27,0)),"check name")) | H21: Medium | I21: Same reasoning as green financing. Verify. | J21: Yes
A22: 21 | B22: Environmental | C22: nature-positive | D22: Core | E22: Ecological Impacts | G22: =IF(OR(E22="",E22="No SASB category"),"",IFERROR(INDEX('SASB categories'!$A$2:$A$27,MATCH(E22,'SASB categories'!$B$2:$B$27,0)),"check name")) | H22: High | J22: Yes
A23: 22 | B23: Environmental | C23: nature-related | D23: Core | E23: Ecological Impacts | G23: =IF(OR(E23="",E23="No SASB category"),"",IFERROR(INDEX('SASB categories'!$A$2:$A$27,MATCH(E23,'SASB categories'!$B$2:$B$27,0)),"check name")) | H23: Medium | I23: Often appears as 'nature-related risks'. | J23: Yes
A24: 23 | B24: Social | C24: diversity and inclusion | D24: Core | E24: Employee Engagement, Diversity & Inclusion | G24: =IF(OR(E24="",E24="No SASB category"),"",IFERROR(INDEX('SASB categories'!$A$2:$A$27,MATCH(E24,'SASB categories'!$B$2:$B$27,0)),"check name")) | H24: High | J24: Yes
A25: 24 | B25: Social | C25: gender diversity | D25: Core | E25: Employee Engagement, Diversity & Inclusion | G25: =IF(OR(E25="",E25="No SASB category"),"",IFERROR(INDEX('SASB categories'!$A$2:$A$27,MATCH(E25,'SASB categories'!$B$2:$B$27,0)),"check name")) | H25: Medium | I25: Often refers to the board rather than the workforce; the benchmark article found the same. | J25: Yes
A26: 25 | B26: Social | C26: human rights | D26: Core | E26: Human Rights & Community Relations | G26: =IF(OR(E26="",E26="No SASB category"),"",IFERROR(INDEX('SASB categories'!$A$2:$A$27,MATCH(E26,'SASB categories'!$B$2:$B$27,0)),"check name")) | H26: High | J26: Yes
A27: 26 | B27: Social | C27: employee wellbeing | D27: Core | E27: Employee Health & Safety | F27: Labor Practices | G27: =IF(OR(E27="",E27="No SASB category"),"",IFERROR(INDEX('SASB categories'!$A$2:$A$27,MATCH(E27,'SASB categories'!$B$2:$B$27,0)),"check name")) | H27: Medium | J27: Yes
A28: 27 | B28: Social | C28: employee training | D28: Core | E28: Employee Engagement, Diversity & Inclusion | G28: =IF(OR(E28="",E28="No SASB category"),"",IFERROR(INDEX('SASB categories'!$A$2:$A$27,MATCH(E28,'SASB categories'!$B$2:$B$27,0)),"check name")) | H28: Medium | I28: SASB places workforce skills under this category in several industries. | J28: Yes
A29: 28 | B29: Social | C29: health and safety | D29: Core | E29: Employee Health & Safety | F29: Product Quality & Safety | G29: =IF(OR(E29="",E29="No SASB category"),"",IFERROR(INDEX('SASB categories'!$A$2:$A$27,MATCH(E29,'SASB categories'!$B$2:$B$27,0)),"check name")) | H29: High | I29: Mostly workplace safety; sometimes product or customer safety. | J29: Yes
A30: 29 | B30: Social | C30: community investment | D30: Core | E30: Human Rights & Community Relations | G30: =IF(OR(E30="",E30="No SASB category"),"",IFERROR(INDEX('SASB categories'!$A$2:$A$27,MATCH(E30,'SASB categories'!$B$2:$B$27,0)),"check name")) | H30: Medium | J30: Yes
A31: 30 | B31: Social | C31: community development | D31: Core | E31: Human Rights & Community Relations | F31: Access & Affordability | G31: =IF(OR(E31="",E31="No SASB category"),"",IFERROR(INDEX('SASB categories'!$A$2:$A$27,MATCH(E31,'SASB categories'!$B$2:$B$27,0)),"check name")) | H31: Medium | I31: For banks it can mean development lending. | J31: Yes
A32: 31 | B32: Social | C32: financial inclusion | D32: Financial add-on | E32: Access & Affordability | G32: =IF(OR(E32="",E32="No SASB category"),"",IFERROR(INDEX('SASB categories'!$A$2:$A$27,MATCH(E32,'SASB categories'!$B$2:$B$27,0)),"check name")) | H32: High | I32: Core SASB topic for commercial banks. | J32: Yes
A33: 32 | B33: Social | C33: responsible lending | D33: Financial add-on | E33: Selling Practices & Product Labeling | G33: =IF(OR(E33="",E33="No SASB category"),"",IFERROR(INDEX('SASB categories'!$A$2:$A$27,MATCH(E33,'SASB categories'!$B$2:$B$27,0)),"check name")) | H33: Medium | J33: Yes
A34: 33 | B34: Social | C34: fair lending | D34: Financial add-on | E34: Access & Affordability | F34: Selling Practices & Product Labeling | G34: =IF(OR(E34="",E34="No SASB category"),"",IFERROR(INDEX('SASB categories'!$A$2:$A$27,MATCH(E34,'SASB categories'!$B$2:$B$27,0)),"check name")) | H34: Low | I34: Verify against SASB's mortgage and consumer finance topics. | J34: Yes
A35: 34 | B35: Social | C35: customer privacy | D35: Core | E35: Customer Privacy | G35: =IF(OR(E35="",E35="No SASB category"),"",IFERROR(INDEX('SASB categories'!$A$2:$A$27,MATCH(E35,'SASB categories'!$B$2:$B$27,0)),"check name")) | H35: High | J35: Yes
A36: 35 | B36: Social | C36: customer satisfaction | D36: Core | E36: No SASB category | G36: =IF(OR(E36="",E36="No SASB category"),"",IFERROR(INDEX('SASB categories'!$A$2:$A$27,MATCH(E36,'SASB categories'!$B$2:$B$27,0)),"check name")) | H36: Medium | I36: SASB has no general customer-satisfaction topic. | J36: Yes
A37: 36 | B37: Social | C37: zakat | D37: Core | E37: No SASB category | G37: =IF(OR(E37="",E37="No SASB category"),"",IFERROR(INDEX('SASB categories'!$A$2:$A$27,MATCH(E37,'SASB categories'!$B$2:$B$27,0)),"check name")) | H37: Medium | I37: QUESTION: often appears as a tax or accounting item rather than social disclosure. Keep in the term list? | J37: Yes
A38: 37 | B38: Social | C38: CSR | D38: Generic – proposed | G38: =IF(OR(E38="",E38="No SASB category"),"",IFERROR(INDEX('SASB categories'!$A$2:$A$27,MATCH(E38,'SASB categories'!$B$2:$B$27,0)),"check name")) | I38: QUESTION: as generic as 'sustainability'. Proposed: count separately with the four generic terms. | J38: Yes
A39: 38 | B39: Social | C39: financial literacy | D39: Financial add-on | E39: Access & Affordability | G39: =IF(OR(E39="",E39="No SASB category"),"",IFERROR(INDEX('SASB categories'!$A$2:$A$27,MATCH(E39,'SASB categories'!$B$2:$B$27,0)),"check name")) | H39: High | I39: Part of SASB's financial inclusion topic for banks. | J39: Yes
A40: 39 | B40: Social | C40: accessibility | D40: Core | E40: Access & Affordability | G40: =IF(OR(E40="",E40="No SASB category"),"",IFERROR(INDEX('SASB categories'!$A$2:$A$27,MATCH(E40,'SASB categories'!$B$2:$B$27,0)),"check name")) | H40: Low | I40: Ambiguous word (building, digital or product access). Check sample matches. | J40: Yes
...

Sheet Industry materiality
A1: SASB industry | B1: SASB disclosure topic | C1: SASB category (General Issue Category) | D1: Confidence in category placement | E1: Companies in our sample | F1: Checked in SASB Navigator? | G1: Comment
A2: Commercial Banks | B2: Data Security | C2: Data Security | D2: High | E2: =COUNTIF('Company industries'!$H$2:$H$66,A2) | F2: Yes
A3: Commercial Banks | B3: Financial Inclusion & Capacity Building | C3: Access & Affordability | D3: High | E3: =COUNTIF('Company industries'!$H$2:$H$66,A3) | F3: Yes
A4: Commercial Banks | B4: Incorporation of ESG Factors in Credit Analysis | C4: Product Design & Lifecycle Management | D4: Medium | E4: =COUNTIF('Company industries'!$H$2:$H$66,A4) | F4: Yes
A5: Commercial Banks | B5: Financed Emissions | C5: GHG Emissions | D5: Medium | E5: =COUNTIF('Company industries'!$H$2:$H$66,A5) | F5: Yes
A6: Commercial Banks | B6: Business Ethics | C6: Business Ethics | D6: High | E6: =COUNTIF('Company industries'!$H$2:$H$66,A6) | F6: Yes
A7: Commercial Banks | B7: Systemic Risk Management | C7: Systemic Risk Management | D7: High | E7: =COUNTIF('Company industries'!$H$2:$H$66,A7) | F7: Yes
A8: Asset Management & Custody Activities | B8: Transparent Information & Fair Advice for Customers | C8: Selling Practices & Product Labeling | D8: High | E8: =COUNTIF('Company industries'!$H$2:$H$66,A8) | F8: Yes
A9: Asset Management & Custody Activities | B9: Employee Diversity & Inclusion | C9: Employee Engagement, Diversity & Inclusion | D9: High | E9: =COUNTIF('Company industries'!$H$2:$H$66,A9) | F9: Yes
A10: Asset Management & Custody Activities | B10: Incorporation of ESG Factors in Investment Management & Advisory | C10: Product Design & Lifecycle Management | D10: Medium | E10: =COUNTIF('Company industries'!$H$2:$H$66,A10) | F10: Yes
A11: Asset Management & Custody Activities | B11: Business Ethics | C11: Business Ethics | D11: High | E11: =COUNTIF('Company industries'!$H$2:$H$66,A11) | F11: Yes
A12: Asset Management & Custody Activities | B12: Systemic Risk Management | C12: Systemic Risk Management | D12: High | E12: =COUNTIF('Company industries'!$H$2:$H$66,A12) | F12: Yes
A13: Telecommunication Services | B13: Environmental Footprint of Operations | C13: Energy Management | D13: High | E13: =COUNTIF('Company industries'!$H$2:$H$66,A13) | F13: Yes
... A169: Hotels & Lodging | B169: Climate Change Adaptation | C169: Physical Impacts of Climate Change | D169: High | E169: =COUNTIF('Company industries'!$H$2:$H$66,A169) | F169: Yes

Sheet SASB categories
A1: Dimension | B1: SASB General Issue Category | C1: In plain terms | D1: Verity terms mapped (primary or secondary) | E1: Industries in our sample where material | F1: Drop-down list
A2: Environment | B2: GHG Emissions | C2: Greenhouse gas emissions from the company's own operations | D2: =COUNTIF('Term mapping'!$E$2:$E$68,B2)+COUNTIF('Term mapping'!$F$2:$F$68,B2) | E2: =SUMPRODUCT(('Industry materiality'!$C$2:$C$169=B2)/COUNTIFS('Industry materiality'!$A$2:$A$169,'Industry materiality'!$A$2:$A$169,'Industry materiality'!$C$2:$C$169,'Industry materiality'!$C$2:$C$169)) | F2: =B2
A3: Environment | B3: Air Quality | C3: Air pollutants other than greenhouse gases, such as dust, NOx and SOx | D3: =COUNTIF('Term mapping'!$E$2:$E$68,B3)+COUNTIF('Term mapping'!$F$2:$F$68,B3) | E3: =SUMPRODUCT(('Industry materiality'!$C$2:$C$169=B3)/COUNTIFS('Industry materiality'!$A$2:$A$169,'Industry materiality'!$A$2:$A$169,'Industry materiality'!$C$2:$C$169,'Industry materiality'!$C$2:$C$169)) | F3: =B3
A4: Environment | B4: Energy Management | C4: How much energy the company uses, how efficiently, and from which sources | D4: =COUNTIF('Term mapping'!$E$2:$E$68,B4)+COUNTIF('Term mapping'!$F$2:$F$68,B4) | E4: =SUMPRODUCT(('Industry materiality'!$C$2:$C$169=B4)/COUNTIFS('Industry materiality'!$A$2:$A$169,'Industry materiality'!$A$2:$A$169,'Industry materiality'!$C$2:$C$169,'Industry materiality'!$C$2:$C$169)) | F4: =B4
A5: Environment | B5: Water & Wastewater Management | C5: Water use, discharge and exposure to water scarcity | D5: =COUNTIF('Term mapping'!$E$2:$E$68,B5)+COUNTIF('Term mapping'!$F$2:$F$68,B5) | E5: =SUMPRODUCT(('Industry materiality'!$C$2:$C$169=B5)/COUNTIFS('Industry materiality'!$A$2:$A$169,'Industry materiality'!$A$2:$A$169,'Industry materiality'!$C$2:$C$169,'Industry materiality'!$C$2:$C$169)) | F5: =B5
A6: Environment | B6: Waste & Hazardous Materials Management | C6: Waste generated and handling of hazardous materials | D6: =COUNTIF('Term mapping'!$E$2:$E$68,B6)+COUNTIF('Term mapping'!$F$2:$F$68,B6) | E6: =SUMPRODUCT(('Industry materiality'!$C$2:$C$169=B6)/COUNTIFS('Industry materiality'!$A$2:$A$169,'Industry materiality'!$A$2:$A$169,'Industry materiality'!$C$2:$C$169,'Industry materiality'!$C$2:$C$169)) | F6: =B6
A7: Environment | B7: Ecological Impacts | C7: Effects on land, ecosystems and biodiversity | D7: =COUNTIF('Term mapping'!$E$2:$E$68,B7)+COUNTIF('Term mapping'!$F$2:$F$68,B7) | E7: =SUMPRODUCT(('Industry materiality'!$C$2:$C$169=B7)/COUNTIFS('Industry materiality'!$A$2:$A$169,'Industry materiality'!$A$2:$A$169,'Industry materiality'!$C$2:$C$169,'Industry materiality'!$C$2:$C$169)) | F7: =B7
A8: Social Capital | B8: Human Rights & Community Relations | C8: Relations with local communities and respect for human rights | D8: =COUNTIF('Term mapping'!$E$2:$E$68,B8)+COUNTIF('Term mapping'!$F$2:$F$68,B8) | E8: =SUMPRODUCT(('Industry materiality'!$C$2:$C$169=B8)/COUNTIFS('Industry materiality'!$A$2:$A$169,'Industry materiality'!$A$2:$A$169,'Industry materiality'!$C$2:$C$169,'Industry materiality'!$C$2:$C$169)) | F8: =B8
A9: Social Capital | B9: Customer Privacy | C9: How customers' personal data is used | D9: =COUNTIF('Term mapping'!$E$2:$E$68,B9)+COUNTIF('Term mapping'!$F$2:$F$68,B9) | E9: =SUMPRODUCT(('Industry materiality'!$C$2:$C$169=B9)/COUNTIFS('Industry materiality'!$A$2:$A$169,'Industry materiality'!$A$2:$A$169,'Industry materiality'!$C$2:$C$169,'Industry materiality'!$C$2:$C$169)) | F9: =B9
A10: Social Capital | B10: Data Security | C10: Protecting data and systems from breaches | D10: =COUNTIF('Term mapping'!$E$2:$E$68,B10)+COUNTIF('Term mapping'!$F$2:$F$68,B10) | E10: =SUMPRODUCT(('Industry materiality'!$C$2:$C$169=B10)/COUNTIFS('Industry materiality'!$A$2:$A$169,'Industry materiality'!$A$2:$A$169,'Industry materiality'!$C$2:$C$169,'Industry materiality'!$C$2:$C$169)) | F10: =B10
A11: Social Capital | B11: Access & Affordability | C11: Fair access to the company's products and services | D11: =COUNTIF('Term mapping'!$E$2:$E$68,B11)+COUNTIF('Term mapping'!$F$2:$F$68,B11) | E11: =SUMPRODUCT(('Industry materiality'!$C$2:$C$169=B11)/COUNTIFS('Industry materiality'!$A$2:$A$169,'Industry materiality'!$A$2:$A$169,'Industry materiality'!$C$2:$C$169,'Industry materiality'!$C$2:$C$169)) | F11: =B11
A12: Social Capital | B12: Product Quality & Safety | C12: Safety and quality of products; recalls | D12: =COUNTIF('Term mapping'!$E$2:$E$68,B12)+COUNTIF('Term mapping'!$F$2:$F$68,B12) | E12: =SUMPRODUCT(('Industry materiality'!$C$2:$C$169=B12)/COUNTIFS('Industry materiality'!$A$2:$A$169,'Industry materiality'!$A$2:$A$169,'Industry materiality'!$C$2:$C$169,'Industry materiality'!$C$2:$C$169)) | F12: =B12
A13: Social Capital | B13: Customer Welfare | C13: Effects of products on customers' health and wellbeing | D13: =COUNTIF('Term mapping'!$E$2:$E$68,B13)+COUNTIF('Term mapping'!$F$2:$F$68,B13) | E13: =SUMPRODUCT(('Industry materiality'!$C$2:$C$169=B13)/COUNTIFS('Industry materiality'!$A$2:$A$169,'Industry materiality'!$A$2:$A$169,'Industry materiality'!$C$2:$C$169,'Industry materiality'!$C$2:$C$169)) | F13: =B13
... A27: Leadership & Governance | B27: Systemic Risk Management | C27: Risks the company poses to the wider financial system or economy | D27: =COUNTIF('Term mapping'!$E$2:$E$68,B27)+COUNTIF('Term mapping'!$F$2:$F$68,B27) | E27: =SUMPRODUCT(('Industry materiality'!$C$2:$C$169=B27)/COUNTIFS('Industry materiality'!$A$2:$A$169,'Industry materiality'!$A$2:$A$169,'Industry materiality'!$C$2:$C$169,'Industry materiality'!$C$2:$C$169)) | F27: =B27
F28: No SASB category
B30: Column F feeds the 'Change to' drop-down on the Term mapping sheet.

Sheet SASB industries
A1: SASB sector | B1: SASB industry | C1: Companies in our sample
A2: Consumer Goods | B2: Apparel, Accessories & Footwear | C2: =COUNTIF('Company industries'!$H$2:$H$66,B2)
A3: Consumer Goods | B3: Appliance Manufacturing | C3: =COUNTIF('Company industries'!$H$2:$H$66,B3)
A4: Consumer Goods | B4: Building Products & Furnishings | C4: =COUNTIF('Company industries'!$H$2:$H$66,B4)
A5: Consumer Goods | B5: E-Commerce | C5: =COUNTIF('Company industries'!$H$2:$H$66,B5)
A6: Consumer Goods | B6: Household & Personal Products | C6: =COUNTIF('Company industries'!$H$2:$H$66,B6)
A7: Consumer Goods | B7: Multiline and Specialty Retailers & Distributors | C7: =COUNTIF('Company industries'!$H$2:$H$66,B7)
A8: Consumer Goods | B8: Toys & Sporting Goods | C8: =COUNTIF('Company industries'!$H$2:$H$66,B8)
A9: Extractives & Minerals Processing | B9: Coal Operations | C9: =COUNTIF('Company industries'!$H$2:$H$66,B9)
A10: Extractives & Minerals Processing | B10: Construction Materials | C10: =COUNTIF('Company industries'!$H$2:$H$66,B10)
A11: Extractives & Minerals Processing | B11: Iron & Steel Producers | C11: =COUNTIF('Company industries'!$H$2:$H$66,B11)
A12: Extractives & Minerals Processing | B12: Metals & Mining | C12: =COUNTIF('Company industries'!$H$2:$H$66,B12)
A13: Extractives & Minerals Processing | B13: Oil & Gas – Exploration & Production | C13: =COUNTIF('Company industries'!$H$2:$H$66,B13)
... A78: Transportation | B78: Road Transportation | C78: =COUNTIF('Company industries'!$H$2:$H$66,B78)
